# Promise 对象

## 1.Promise 的含义

Promise 是异步编程的一种解决方案, 比回调和事件更合理和强大.

Promise 简单来说是一个容器, 里面保存着一个异步操作的结果. 从语法上说, 可以获取异步操作的消息.

`Promise`对象有两个特点:

1. 对象的状态不受外界影响. `Promise`对象代表一个异步操作, 有三种状态: `pending`(进行中) `fulfilled`(已成功) `rejected`(已失败). 只有异步操作的结果可以采编这个状态.

2. 一旦状态改变就不会再变, 任何时候都可以得到这个结果. Promise 对象的状态改变只有两种情况: 从`pending`变为`fulfilled`和从`pending`变为`rejected`. 只要这两种情况发生了, 状态就凝固不会再改变了. 即使再对`Promise`对象添加回调函数也会立即得到这个结果. 与事件不同, 事件如果错过了再去监听是得不到结果的.

`Promise`也有一些缺点. 首先无法取消, 一旦新建就会立即执行, 无法中途取消. 另外如果不设置回调函数, `Promise`内部抛出的错误不会反映到外部. 第三当处于`pending`状态时, 无法得知目前进展到哪一阶段.

## 2.基本用法

`Promise`对象是一个构造函数, 用来生成`Promise`实例, 接受一个函数作为参数, 这个函数的参数分别是`resolve`和`reject`.

```js
const promise = new Promise(function(resolve, reject) {
  // ... some code

  if (/* 异步操作成功 */){
    resolve(value);
  } else {
    reject(error);
  }
});
```

`resolve`函数的作用是将`Promise`对象的状态从`pending`变为`fulfilled`, 异步操作成功时将结果作为参数传递出去; `reject`函数时将`Promise`对象的状态从`pending`变为`rejected`, 并将异步操作失败报出的错误作为参数传递出去.

`Promise`实例生成以后, 可以用`then`方法分别指定`resolve`状态和`reject`状态的回调函数.

```js
promise.then(
  function (value) {
    // success
  },
  function (error) {
    // failure
  }
);
```

调用`resolve`和`reject`函数如果带有参数, 那么这个参数会传递给回调函数. `reject`函数的参数通常是`Error`对象的实例; `resolve`函数的参数除了正常值以外, 还可以是另一个`Promise`实例:

```js
const p1 = new Promise(function (resolve, reject) {
  setTimeout(() => {
    console.log("p1");
    reject(new Error("fail"));
  }, 1000);
});

const p2 = new Promise(function (resolve, reject) {
  setTimeout(() => {
    console.log("p2");
    resolve(p1);
  }, 3000);
});

p2.then((result) => console.log(result)).catch((error) => console.log(error));
// p1
// Error: fail
```

注意此时`p1`的状态会传递给`p2`, 也就是说`p1`的状态决定了`p2`的状态. 如果`p1`状态是`pending`, 那么`p2`的回调函数会等待`p1`的状态改变; 如果`p1`的状态已经是`resolved`或者`rejected`, 那么`p2`的回调函数会立即执行.

注意: 调用`resolve`或者`reject`不会终止`Promise`的参数函数的执行.

```js
new Promise((resolve, reject) => {
  resolve(1);
  console.log(2);
}).then((r) => {
  console.log(r);
});
// 2
// 1
```

## 3.Promise.prototype.then()

`then`的作用是为`Promise`实例添加状态改变时的回调函数. 第一个参数是`resolved`状态的回调函数, 第二个参数是`rejected`的回调函数, 都是可选的.

`then`方法返回的是一个新的`Promise`实例. 因此可以采用链式写法:

```js
getJSON("/posts.json")
  .then(function (json) {
    return json.post;
  })
  .then(function (post) {
    // ...
  });

getJSON("/post/1.json")
  .then((post) => getJSON(post.commentURL))
  .then(
    (comments) => console.log("resolved: ", comments),
    (err) => console.log("rejected: ", err)
  );
```

## 4.Promise.prototype.catch()

`Promise.prototype.catch()`方法是`.then(null, rejection)`或`.then(undefined, rejection)`的别名, 用于指定发生错误时的回调函数.

```js
getJSON("/posts.json")
  .then(function (posts) {
    // ...
  })
  .catch(function (error) {
    // 处理 getJSON 和 前一个回调函数运行时发生的错误
    console.log("发生错误！", error);
  });
```

`promise`抛出一个错误, 就会被`catch()`方法指定的回调函数捕获. 因此`reject()`方法等同于抛出错误:

```js
// 写法一
const promise = new Promise(function (resolve, reject) {
  try {
    throw new Error("test");
  } catch (e) {
    reject(e);
  }
});
promise.catch(function (error) {
  console.log(error);
});

// 写法二
const promise = new Promise(function (resolve, reject) {
  reject(new Error("test"));
});
promise.catch(function (error) {
  console.log(error);
});
```

Promise 对象的错误具有"冒泡"的性质, 会一直向后传递, 知道被捕获位置. 也就是说错误总是会被下一个`catch`语句捕获.

```js
getJSON("/post/1.json")
  .then(function (post) {
    return getJSON(post.commentURL);
  })
  .then(function (comments) {
    // some code
  })
  .catch(function (error) {
    // 处理前面三个Promise产生的错误
  });
```

一般来说不会在`then()`方法里面定义`rejected`状态的回调函数(即`then`的第二个参数), 总是使用`catch`方法:

```js
// bad
promise.then(
  function (data) {
    // success
  },
  function (err) {
    // error
  }
);

// good
promise
  .then(function (data) {
    //cb
    // success
  })
  .catch(function (err) {
    // error
  });
```

与传统的`try/catch`代码不同, 如果没有使用`catch()`方法指定错误处理的回调函数, `Promise`对象抛出的错误不会传递到外层代码, 不会有任何反应, 也不会对外部的代码造成影响. 但是如果在`Node`环境中有未捕获的错误, 会直接终止进程, 并且进程的退出码不为 0.

在`Node.js`里面有一个默认`unhandledRejection`事件, 专门监听未捕获的`reject`错误:

```js
process.on("unhandledRejection", function (err, p) {
  throw err;
});
```

一般总是建议在 Promise 对象后面跟着`catch()`方法, 可以处理 Promise 内部发生的错误.

`catch()`方法的返回值也是一个 Promise 对象, 因此可以链式调用.

## 5.Promise.prototype.finally()

ES2018 引入了`finally()`方法, 不管 Promise 对象最后状态如何, 都会执行.

```js
promise
  .then((result) => {
    // ···
  })
  .catch((error) => {
    // ···
  })
  .finally(() => {
    // ···
  });
```

`finally()`的回调函数不接受任何参数, 意味着没办法知道前面的 Promise 状态到底是`fulfilled`还是`rejected`. 这表明`finally`方法里面的操作与状态无关, 不依赖于`Promise`的执行结果.

`finally()`本质上是`then()`的特例.

```js
promise.finally(() => {
  // 语句
});

// 等同于
promise.then(
  (result) => {
    // 语句
    return result;
  },
  (error) => {
    // 语句
    throw error;
  }
);
```

## 6.Promise.all()

`Promise.all()`方法用于多个`Promise`实例, 包装成一个新的 Promise 实例. 当这些`Promise`实例的状态全部变成`fulfilled`, `Promise.all`的状态才会变成`fulfilled`, 同时将所有实例的返回值组成数组传递给回调函数; 如果有一个状态变成`rejected`, 那么`Promise.all`的状态会变成`rejected`, 同时将第一个变成`rejected`实例的返回值传递给回调函数.

`Promise.all()`方法接受一个 Promise 实例的数组作为参数, 如果参数不是数组会将参数通过`Promise.resolve()`方法转为 Promise 实例. `Promise.all`方法的参数可以不是数组, 但必须有`Iterator`接口, 且返回的每个成员都是 Promise 实例.

```js
const p = Promise.all([p1, p2, p3]);
```

如果作为参数的`Promise`实例定义了`catch`方法, 那么它一旦被`rejected`, 并不会触发`Promise.all`的`catch`方法.

```js
const p1 = new Promise((resolve, reject) => {
  resolve("hello");
})
  .then((result) => result)
  .catch((e) => e);

const p2 = new Promise((resolve, reject) => {
  throw new Error("报错了");
})
  .then((result) => result)
  .catch((e) => e);

Promise.all([p1, p2])
  .then((result) => console.log(result))
  .catch((e) => console.log(e));
// ["hello", Error: 报错了]
```

## 7.Promise.race()

`Promise.race()`方法同样是将多个`Promise`实例包装成一个新的`Promise`实例. 只要多个`Promise`实例中, 有一个实例率先改变状态, 那么`Promise.race()`实例的状态就跟着改变. 率先改变状态的`Promise`实例的返回值就会传递给`Promise.race()`实例的回调函数.

`Promise.race()`方法的参数与`Promise.all()`一样, 如果不是`Promise`实例, 就会先调用`Promise.resolve()`将参数转变为`Promise`实例.

```js
const p = Promise.race([p1, p2, p3]);
```

## 8.Promise.allSettled()

ES2020 引入了`Promise.allSettled()`方法, 当一组异步操作都结束了才会返回一个新的 Promise 对象(不管是`fulfilled`还是`rejected`). 返回的新的 Promise 实例的状态总是`fulfilled`, 它的回调函数接受到一个数组作为参数, 该数组为前面数组的每个 Promise 对象.

```js
const resolved = Promise.resolve(42);
const rejected = Promise.reject(-1);

const allSettledPromise = Promise.allSettled([resolved, rejected]);

allSettledPromise.then(function (results) {
  console.log(results);
});
// [
//    { status: 'fulfilled', value: 42 },
//    { status: 'rejected', reason: -1 }
// ]
```

`results`的每一个成员都是对象, 对象的格式是固定的, 对应异步操作的结果:

```js
// 异步操作成功时
// {status: 'fulfilled', value: value}

// 异步操作失败时
// {status: 'rejected', reason: reason}
```

## 9.Promise.any()

ES2021 引入了`Promise.any()`方法, 该方法接受一组 Promise 实例作为参数, 包装成一个新的 Promise 实例返回. 只要参数实例有一个变成`fulfilled`状态, 包装实例就会变成`fulfilled`状态; 如果所有参数实例都变成`rejected`状态, 包装实例就会变成`rejected`状态.

`Promise.any`抛出的错误是一个`AggregateError`实例, 相当于一个数组, 每个成员对应一个被`rejected`的操作所抛出的错误.

```js
var resolved = Promise.resolve(42);
var rejected = Promise.reject(-1);
var alsoRejected = Promise.reject(Infinity);

Promise.any([resolved, rejected, alsoRejected]).then(function (result) {
  console.log(result); // 42
});

Promise.any([rejected, alsoRejected]).catch(function (results) {
  console.log(results); // [AggregateError: All promises were rejected]
});
```

## 10.Promise.resolve()

`Promise.resolve()`可以将现有对象转为`Promise`对象:

```js
Promise.resolve("foo");
// 等价于
new Promise((resolve) => resolve("foo"));
```

`Promise.resolve()`方法的参数分为下面四种情况:

1. 参数是一个`Promise`实例

如果参数是 Promise 实例, 那么`Promise.resolve()`将不做任何修改, 原封不动的返回这个实例.

```js
const p1 = Promise.resolve(
  new Promise((resolve, reject) => {
    reject("something error");
  })
)
  .then((res) => {
    console.log("res: ", res);
  })
  .catch((err) => {
    console.log("err: ", err);
  });
// err:  something error
```

2. 参数是一个`thenable`对象

`thenable`对象是指具有`then`方法的对象, 比如下面的对象:

```js
let thenable = {
  then: function (resolve, reject) {
    resolve(42);
  },
};
```

`Promise.resolve()`会将这个对象转为 Promise 对象, 然后立即执行`thenable`对象的`then`方法:

```js
let p1 = Promise.resolve(thenable);
p1.then(function (value) {
  console.log(value); // 42
});
```

3. 参数不是具有`then()`方法的对象, 或者根本不是对象

如果参数是一个原始值, 或者不具有`then`方法, 那么`Promise.resolve()`方法返回一个新的 Promise 对象, 状态为`resolved`

```js
const p = Promise.resolve("Hello");

p.then(function (s) {
  console.log(s);
});
// Hello
```

4. 不带有任何参数

`Promise.resolve()`允许调用时不带任何参数, 直接返回一个`resolved`状态的 Promise 对象.

## 11.Promise.reject()

`Promise.reject(reason)`方法也会返回一个新的 Promise 实例, 该实例的状态为`rejected`.

```js
const p = Promise.reject("出错了");
// 等同于
const p = new Promise((resolve, reject) => reject("出错了"));

p.then(null, function (s) {
  console.log(s);
});
// 出错了
```

`Promise.reject()`方法的参数会原封不动的作为`reject`的理由, 变成后续方法的参数.

## 12.应用

### 加载图片

将图片的加载写成一个 Promise, 一旦加载完成, Promise 的状态就发生改变.

```js
const preloadImage = function (path) {
  return new Promise(function (resolve, reject) {
    const image = new Image();
    image.onload = resolve;
    image.onerror = reject;
    image.src = path;
  });
};
```

### Generator 函数与 Promise 的结合

```js
function getFoo() {
  return new Promise(function (resolve, reject) {
    resolve("foo");
  });
}

const g = function* () {
  try {
    const foo = yield getFoo();
    console.log(foo);
  } catch (e) {
    console.log(e);
  }
};

function run(generator) {
  const it = generator();

  function go(result) {
    if (result.done) return result.value;

    return result.value.then(
      function (value) {
        return go(it.next(value));
      },
      function (error) {
        return go(it.throw(error));
      }
    );
  }

  go(it.next());
}

run(g);
```

## 13.Promise.try()

实际开发中经常会遇到一种情况: 不知道或者不想区分函数`f`是同步还是异步的, 但是想用 Promise 来处理, 这样就可以统一使用`then`和`catch`处理. 一般会采用下面的写法:

```js
Promise.resolve().then(f);
```

```js
const f = () => console.log("now");
Promise.resolve().then(f);
console.log("next");
// next
// now
```

但是这样包装之后就变成异步操作了, 会影响执行的顺序. 那么如何不影响执行顺序呢, 有两种写法, 一种是使用`async`函数来写:

```js
const f = () => console.log("now");
(async () => f())();
console.log("next");
// now
// next
```

第二种写法是`new Promise()`:

```js
const f = () => console.log("now");
(() => new Promise((resolve) => resolve(f())))();
console.log("next");
// now
// next
```

现在有一个提案, 提供`Promise.try()`方法替代上面的写法:

```js
const f = () => console.log("now");
Promise.try(f);
console.log("next");
// now
// next
```

`Promise.try`为所有操作提供了统一的处理机制, 所以想要使用`then`方法管理流程最后都使用`Promise.try`包装一下, 这样可以更好地管理异常.

```js
function getUsername(userId) {
  return database.users.get({ id: userId }).then(function (user) {
    return user.name;
  });
}
```

上面代码中`database.users.get()`返回一个 Promise 对象, 如果抛出异步错误, 可以用 catch 方法捕获, 但是如果抛出同步错误, 就不得不用`try...catch`去捕获:

```js
try {
  database.users
    .get({ id: userId })
    .then(() => {
      // ...
    })
    .catch(() => {
      // 异步错误
    });
} catch (e) {
  // 同步错误
}
```

这时可以使用的`Promise.try()`来包裹函数, 统一使用`catch`来处理异常

```js
Promise.try(() => database.users.get({ id: userId }))
  .then()
  .catch();
```
